Workbook

Sheet Inputs
C2: Units | D2: Total | E2: 2025 | F2: 2026 | G2: 2027 | H2: 2028 | I2: 2029 | J2: 2030 | K2: 2031 | L2: 2032 | M2: 2033 | N2: 2034 | O2: 2035 | P2: 2036 | Q2: 2037 | R2: 2038 | S2: 2039 | T2: 2040 | U2: 2041 | V2: 2042 | W2: 2043 | X2: 2044 | Y2: 2045 | Z2: 2046 | AA2: 2047 | AB2: 2048 | AC2: 2049 | AD2: 2050 | AE2: 2051 | AF2: 2052 | AG2: 2053 | AH2: 2054 | AI2: 2055 | AJ2: 2056 | AK2: 2057 | AL2: 2058 | AM2: 2059 | AN2: 2060 | AO2: 2061 | AP2: 2062 | AQ2: 2063 | AR2: 2064
B3: Carbon Credits Issued | C3: Credits | D3: =SUM(E3:AR3) -> 10002623 | E3: 0 | F3: 0 | G3: 0 | H3: 510.565 | I3: 3423.8 | J3: 12061.855 | K3: 35095.33 | L3: 85150.28 | M3: 157885.21 | N3: 246637.51 | O3: 338617.37 | P3: 392048.01 | Q3: 421854.99 | R3: 457601.33 | S3: 473464.19 | T3: 479439.41 | U3: 470634.74 | V3: 459002.95 | W3: 439983.88 | X3: 415157.95 | Y3: 394157.68 | Z3: 370545.05 | AA3: 351173.51 | AB3: 333695.38 | AC3: 308833.79 | AD3: 285229.57 | AE3: 272208.57 | AF3: 259711.07 | AG3: 257921.61 | AH3: 253655.76 | AI3: 241579.12 | AJ3: 232758.14 | AK3: 220841.66 | AL3: 212808.54 | AM3: 204265.93 | AN3: 194076.85 | AO3: 189455.45 | AP3: 184628.96 | AQ3: 177893.56 | AR3: 168613.41
B4: Project Implementation Costs | C4: USD | D4: =SUM(E4:AR4) -> -130130374 | E4: -628486 | F4: -1333184 | G4: -1850593 | H4: -2299308 | I4: -2826901 | J4: -3904718 | K4: -5157758 | L4: -5534824 | M4: -4132931 | N4: -3194954 | O4: -2366182 | P4: -2690986 | Q4: -2668818 | R4: -2755284 | S4: -2841300 | T4: -2855677 | U4: -2943789 | V4: -3032208 | W4: -3048393 | X4: -3137449 | Y4: -3083898 | Z4: -3100184 | AA4: -3190245 | AB4: -3280655 | AC4: -3297989 | AD4: -3389119 | AE4: -3480621 | AF4: -3499070 | AG4: -3591339 | AH4: -3684004 | AI4: -3642446 | AJ4: -3662494 | AK4: -3756396 | AL4: -3777296 | AM4: -3798634 | AN4: -3893852 | AO4: -3916096 | AP4: -3938807 | AQ4: -4035427 | AR4: -2908059
B5: Carbon Price Curve | C5: USD | E5: 40 | F5: 41.6 | G5: 43.26 | H5: 44.99 | I5: 46.79 | J5: 48.67 | K5: 50.61 | L5: 52.64 | M5: 54.74 | N5: 56.93 | O5: 59.21 | P5: 61.58 | Q5: 64.04 | R5: 66.6 | S5: 69.27 | T5: 72.04 | U5: 74.92 | V5: 77.92 | W5: 81.03 | X5: 84.27 | Y5: 87.64 | Z5: 91.15 | AA5: 94.8 | AB5: 98.59 | AC5: 102.53 | AD5: 106.63 | AE5: 110.9 | AF5: 115.33 | AG5: 119.95 | AH5: 124.75 | AI5: 129.74 | AJ5: 134.93 | AK5: 140.32 | AL5: 145.94 | AM5: 151.77 | AN5: 157.84 | AO5: 164.16 | AP5: 170.72 | AQ5: 177.55 | AR5: 184.65
B6: Rubicon Investment | C6: USD | E6: -4000000 | F6: -4000000 | G6: -4000000 | H6: -4000000 | I6: -4000000 | J6: 0 | K6: 0 | L6: 0 | M6: 0 | N6: 0 | O6: 0 | P6: 0 | Q6: 0 | R6: 0 | S6: 0 | T6: 0 | U6: 0 | V6: 0 | W6: 0 | X6: 0 | Y6: 0 | Z6: 0 | AA6: 0 | AB6: 0 | AC6: 0 | AD6: 0 | AE6: 0 | AF6: 0 | AG6: 0 | AH6: 0 | AI6: 0 | AJ6: 0 | AK6: 0 | AL6: 0 | AM6: 0 | AN6: 0 | AO6: 0 | AP6: 0 | AQ6: 0 | AR6: 0
W15: =SUM(#REF!) -> #REF!

Sheet Calculations
A1: RUBICON CARBON - NICARAGUA PROJECT ANALYSIS
A3: ASSUMPTIONS
A5: Streaming Percentage | B5: 0.48
A6: Credit Price Multiplier | B6: 1
A7: Credit Volume Multiplier | B7: 1
A8: Rubicon Investment | B8: 20000000
A10: CARBON CREDIT ALLOCATION
B12: Units | C12: Total | D12: 2025 | E12: 2026 | F12: 2027 | G12: 2028 | H12: 2029 | I12: 2030 | J12: 2031 | K12: 2032 | L12: 2033 | M12: 2034 | N12: 2035 | O12: 2036 | P12: 2037 | Q12: 2038 | R12: 2039 | S12: 2040 | T12: 2041 | U12: 2042 | V12: 2043 | W12: 2044
A13: Project Developer | B13: Credits | C13: =SUM(D13:W13) -> 2542056.1 | D13: =(Inputs!E3*(1-Calculations!$B$5))*$B$7 -> 0 | E13: =(Inputs!F3*(1-Calculations!$B$5))*$B$7 -> 0 | F13: =(Inputs!G3*(1-Calculations!$B$5))*$B$7 -> 0 | G13: =(Inputs!H3*(1-Calculations!$B$5))*$B$7 -> 265.4938 | H13: =(Inputs!I3*(1-Calculations!$B$5))*$B$7 -> 1780.376 | I13: =(Inputs!J3*(1-Calculations!$B$5))*$B$7 -> 6272.1646 | J13: =(Inputs!K3*(1-Calculations!$B$5))*$B$7 -> 18249.572 | K13: =(Inputs!L3*(1-Calculations!$B$5))*$B$7 -> 44278.146 | ... W13: =(Inputs!X3*(1-Calculations!$B$5))*$B$7 -> 215882.14
A14: Rubicon | B14: Credits | C14: =SUM(D14:W14) -> 2346513.3 | D14: =(Inputs!E3*Calculations!$B$5)*$B$7 -> 0 | E14: =(Inputs!F3*Calculations!$B$5)*$B$7 -> 0 | F14: =(Inputs!G3*Calculations!$B$5)*$B$7 -> 0 | G14: =(Inputs!H3*Calculations!$B$5)*$B$7 -> 245.0712 | H14: =(Inputs!I3*Calculations!$B$5)*$B$7 -> 1643.424 | I14: =(Inputs!J3*Calculations!$B$5)*$B$7 -> 5789.6904 | J14: =(Inputs!K3*Calculations!$B$5)*$B$7 -> 16845.758 | K14: =(Inputs!L3*Calculations!$B$5)*$B$7 -> 40872.134 | ... W14: =(Inputs!X3*Calculations!$B$5)*$B$7 -> 199275.82
A16: CASH FLOW ANALYSIS
A18: Rubicon Cash Flows
B19: Units | C19: Total | D19: 2025 | E19: 2026 | F19: 2027 | G19: 2028 | H19: 2029 | I19: 2030 | J19: 2031 | K19: 2032 | L19: 2033 | M19: 2034 | N19: 2035 | O19: 2036 | P19: 2037 | Q19: 2038 | R19: 2039 | S19: 2040 | T19: 2041 | U19: 2042 | V19: 2043 | W19: 2044
A20: Investment | B20: USD | C20: =SUM(D20:W20) -> -20000000 | D20: =Inputs!E6 -> -4000000 | E20: =Inputs!F6 -> -4000000 | F20: =Inputs!G6 -> -4000000 | G20: =Inputs!H6 -> -4000000 | H20: =Inputs!I6 -> -4000000 | I20: =Inputs!J6 -> 0 | J20: =Inputs!K6 -> 0 | K20: =Inputs!L6 -> 0 | ... W20: =Inputs!X6 -> 0
A21: Revenue | B21: USD | C21: =SUM(D21:W21) -> 1.4338936e+08 | D21: =(D14*(Inputs!E5*$B$6)+D20) -> -4000000 | E21: =(E14*(Inputs!F5*$B$6)+E20) -> -4000000 | F21: =(F14*(Inputs!G5*$B$6)+F20) -> -4000000 | G21: =(G14*(Inputs!H5*$B$6)+G20) -> -3988974.2 | H21: =(H14*(Inputs!I5*$B$6)+H20) -> -3923104.2 | I21: =(I14*(Inputs!J5*$B$6)+I20) -> 281784.23 | J21: =(J14*(Inputs!K5*$B$6)+J20) -> 852563.83 | K21: =(K14*(Inputs!L5*$B$6)+K20) -> 2151509.2 | ... W21: =(W14*(Inputs!X5*$B$6)+W20) -> 16792973
A22: Net Flows | B22: USD | C22: =SUM(D22:W22) -> 5.6370951e+08 | D22: =D21 -> -4000000 | E22: =D22+E21 -> -8000000 | F22: =E22+F21 -> -12000000 | G22: =F22+G21 -> -15988974 | H22: =G22+H21 -> -19912078 | I22: =H22+I21 -> -19630294 | J22: =I22+J21 -> -18777730 | K22: =J22+K21 -> -16626221 | L22: =K22+L21 -> -12477756 | ... W22: =V22+W21 -> 1.4338936e+08
A24: Project Developer Cash Flows
B25: Units | C25: Total | D25: 2025 | E25: 2026 | F25: 2027 | G25: 2028 | H25: 2029 | I25: 2030 | J25: 2031 | K25: 2032 | L25: 2033 | M25: 2034 | N25: 2035 | O25: 2036 | P25: 2037 | Q25: 2038 | R25: 2039 | S25: 2040 | T25: 2041 | U25: 2042 | V25: 2043 | W25: 2044
A26: Rubicon Investment | B26: USD | C26: =SUM(D26:W26) -> 20000000 | D26: =-(Inputs!E6) -> 4000000 | E26: =-(Inputs!F6) -> 4000000 | F26: =-(Inputs!G6) -> 4000000 | G26: =-(Inputs!H6) -> 4000000 | H26: =-(Inputs!I6) -> 4000000 | I26: =-(Inputs!J6) -> 0 | J26: =-(Inputs!K6) -> 0 | K26: =-(Inputs!L6) -> 0 | ... W26: =-(Inputs!X6) -> 0
A27: Project Implementation Costs | B27: USD | C27: =SUM(D27:W27) -> -59203743 | D27: =Inputs!E4 -> -628486 | E27: =Inputs!F4 -> -1333184 | F27: =Inputs!G4 -> -1850593 | G27: =Inputs!H4 -> -2299308 | H27: =Inputs!I4 -> -2826901 | I27: =Inputs!J4 -> -3904718 | J27: =Inputs!K4 -> -5157758 | K27: =Inputs!L4 -> -5534824 | ... W27: =Inputs!X4 -> -3137449
A28: Developer Credit Revenue | B28: USD | C28: =SUM(D28:W28) -> 1.7700514e+08 | D28: =D13*Inputs!E5 -> 0 | E28: =E13*Inputs!F5 -> 0 | F28: =F13*Inputs!G5 -> 0 | G28: =G13*Inputs!H5 -> 11944.566 | H28: =H13*Inputs!I5 -> 83303.793 | I28: =I13*Inputs!J5 -> 305266.25 | J28: =J13*Inputs!K5 -> 923610.82 | K28: =K13*Inputs!L5 -> 2330801.6 | ... W28: =W13*Inputs!X5 -> 18192388
A29: Cumulative Cash Balance | B29: USD | D29: =SUM(D26:D28) -> 3371514 | E29: =D29+SUM(E26:E28) -> 6038330 | F29: =E29+SUM(F26:F28) -> 8187737 | G29: =F29+SUM(G26:G28) -> 9900373.6 | H29: =G29+SUM(H26:H28) -> 11156776 | I29: =H29+SUM(I26:I28) -> 7557324.6 | J29: =I29+SUM(J26:J28) -> 3323177.4 | K29: =J29+SUM(K26:K28) -> 119155.01 | L29: =K29+SUM(L26:L28) -> 480395.08 | ... W29: =V29+SUM(W26:W28) -> 1.378014e+08
A31: KEY METRICS
A33: IRR | B33: =IRR(D21:W21) -> 0.2004252
A34: Payback period | B34: {=MATCH(TRUE,D22:W22>=0,0)} -> 11
A35: Minimum Cash Balance | B35: =MIN(D29:W29) -> 119155.01
A37: SENSITIVITY ANALYSIS - IRR TO CREDIT PRICE & VOLUME
A39: IRR Sensitivity Analysis Table
C40: Credit Price Multiplier
A41: Credit Volume Multiplier | B41: =B33 -> 0.2004252 | C41: 0.8 | D41: 0.9 | E41: 0.95 | F41: 1 | G41: 1.05 | H41: 1.1 | I41: 1.2
B42: 0.8 | C42: 0.15191882 | D42: 0.16435567 | E42: 0.17014999 | F42: 0.17569773 | G42: 0.18102123 | H42: 0.18613984 | I42: 0.19582786
B43: 0.9 | C43: 0.16435567 | D43: 0.17704883 | E43: 0.18296376 | F43: 0.18862767 | G43: 0.19406326 | H43: 0.19929022 | I43: 0.20918483
B44: 0.95 | C44: 0.17014999 | D44: 0.18296376 | E44: 0.18893544 | F44: 0.194654 | G44: 0.20014233 | H44: 0.20542027 | I44: 0.21541207
B45: 1 | C45: 0.17569773 | D45: 0.18862767 | E45: 0.194654 | F45: 0.2004252 | G45: 0.20596433 | H45: 0.21129136 | I45: 0.22137676
B46: 1.05 | C46: 0.18102123 | D46: 0.19406326 | E46: 0.20014233 | F46: 0.20596433 | G46: 0.21155246 | H46: 0.21692687 | I46: 0.22710259
B47: 1.1 | C47: 0.18613984 | D47: 0.19929022 | E47: 0.20542027 | F47: 0.21129136 | G47: 0.21692687 | H47: 0.22234706 | I47: 0.23261007
B48: 1.2 | C48: 0.19582786 | D48: 0.20918483 | E48: 0.21541207 | F48: 0.22137676 | G48: 0.22710259 | H48: 0.23261007 | I48: 0.24303948
A52: VOLUME / PRICE CHART
B54: Units | C54: Total | D54: 2025 | E54: 2026 | F54: 2027 | G54: 2028 | H54: 2029 | I54: 2030 | J54: 2031 | K54: 2032 | L54: 2033 | M54: 2034 | N54: 2035 | O54: 2036 | P54: 2037 | Q54: 2038 | R54: 2039 | S54: 2040 | T54: 2041 | U54: 2042 | V54: 2043 | W54: 2044
A55: Carbon Credits Issued | B55: Credits | C55: =SUM(D55:W55) -> 4888569.4 | D55: 0 | E55: 0 | F55: 0 | G55: 510.565 | H55: 3423.8 | I55: 12061.855 | J55: 35095.33 | K55: 85150.28 | L55: 157885.21 | M55: 246637.51 | N55: 338617.37 | O55: 392048.01 | P55: 421854.99 | Q55: 457601.33 | R55: 473464.19 | S55: 479439.41 | T55: 470634.74 | U55: 459002.95 | V55: 439983.88 | W55: 415157.95
...
